<?xml version="1.0"?>
<robot name="sarkofag"
       xmlns:sensor="http://playerstage.sourceforge.net/gazebo/xmlschema/#sensor"
       xmlns:controller="http://playerstage.sourceforge.net/gazebo/xmlschema/#controller"
       xmlns:xacro="http://ros.org/wiki/fixme"
       xmlns:interface="http://playerstage.sourceforge.net/gazebo/xmlschema/#interface">

  <link name="base_link">
    <inertial>
      <mass value="0" />
      <origin xyz="-0.0 0.0 0.0" />
      <inertia ixx="1.0" ixy="0.0" ixz="0.0"
               iyy="1.0" iyz="0.0"
               izz="1.0" />
    </inertial>
    
    <visual>
      <origin xyz="-0.0 0 1.0" rpy="0 0 0" />
      <geometry>
        <box size="0.20 1.5 2.0" />
      </geometry>

      <material name="Cyan">
        <color rgba="0.5 0.5 0.5 1.0"/>
      </material>

    </visual>

    <collision>
      <origin xyz="0 0 1.0" rpy="0 0 0" />
      <geometry>
        <box size="0.2 1.5 2.0" />
      </geometry>
    </collision>
  </link>
  
  <joint name="crank_joint" type="revolute">
    <origin rpy="0 0 0" xyz="-0.2 0 1.0"/>
    <limit lower="0.0" upper="3.14" effort="10.0" velocity="10.0" />
    <parent link="base_link"/>
    <child link="crank_link"/>
  </joint>

  <link name="crank_link">
    <inertial>
      <mass value="0.1"/>
      <origin xyz="0.0 0.0 0.0"/>
      <inertia ixx="0.1" ixy="0" ixz="0" iyy="0.1" iyz="0" izz="0.1"/>
    </inertial>
    
    <visual>
      <origin rpy="0 0 0.0" xyz="0 0 0.3"/>
      <geometry>
        <box size="0.05 0.05 0.8"/>
      </geometry>
    </visual>
    
    <collision>
      <origin rpy="0 0 0.0" xyz="0 0 0.3"/>
      <geometry>
        <box size="0.05 0.05 0.8"/>
      </geometry>
    </collision>
    
  </link>

</robot>
