<?xml version="1.0"?>
<robot name="irp6p"
       xmlns:sensor="http://playerstage.sourceforge.net/gazebo/xmlschema/#sensor"
       xmlns:controller="http://playerstage.sourceforge.net/gazebo/xmlschema/#controller"
       xmlns:xacro="http://ros.org/wiki/fixme"
       xmlns:interface="http://playerstage.sourceforge.net/gazebo/xmlschema/#interface">

  <property name="M_PI" value="3.14159"/>

  <link name="base_link">
    <inertial>
      <mass value="0" />
      <origin xyz="-0.0 0.0 0.0" />
      <inertia ixx="1.0" ixy="0.0" ixz="0.0"
               iyy="1.0" iyz="0.0"
               izz="1.0" />
    </inertial>

    <collision>
      <origin xyz="0 0 0.15" rpy="0 0 0" />
      <geometry>
        <box size="0.4 0.4 0.3" />
      </geometry>
    </collision>
  </link>
  
  <joint name="joint1" type="revolute">
    <origin rpy="0 0 0" xyz="0.0 0.0 0.3"/>
    <axis xyz="0 0 1"/>
    <limit lower="-2.96705973" upper="2.96705973" effort="10.0" velocity="10.0" />
    <parent link="base_link"/>
    <child link="link1"/>
  </joint>

  <link name="link1">
    <inertial>
      <mass value="0.1"/>
      <origin xyz="0.0 0.0 0.0"/>
      <inertia ixx="0.1" ixy="0" ixz="0" iyy="0.1" iyz="0" izz="0.1"/>
    </inertial>
    
    <visual>
      <origin rpy="-1.57 0 0.0" xyz="0 0 0.4"/>
      <geometry>
        <mesh filename="package://irp6_defs/meshes/link1.3ds" scale="0.01 0.01 0.01" />
      </geometry>
    </visual>
    
    <collision>
      <origin rpy="0 0 0.0" xyz="0 0 0.2"/>
      <geometry>
        <box size="0.22 0.25 0.4"/>
      </geometry>
    </collision>
  </link>

  <joint name="joint2" type="revolute">
    <origin rpy="${-0.5 * M_PI} 0 0" xyz="0.0 0.0 0.4"/>
    <axis xyz="0 0 1"/>
    <limit lower="-2.26892803" upper="-0.872664626" effort="10.0" velocity="10.0" />
    <parent link="link1"/>
    <child link="link2"/>
  </joint>

  <link name="link2">
    <inertial>
      <mass value="0.1"/>
      <origin xyz="0.0 0.0 0.0"/>
      <inertia ixx="0.1" ixy="0" ixz="0" iyy="0.1" iyz="0" izz="0.1"/>
    </inertial>
    
    <visual>
      <origin rpy="0 0 0.0" xyz="0.45 0.0 0.0"/>
      <geometry>
        <mesh filename="package://irp6_defs/meshes/link2.3ds" scale="0.01 0.01 0.01" />
      </geometry>
    </visual>
    
    <collision>
      <origin rpy="0 0 0.0" xyz="0.2 0.0 0.0"/>
      <geometry>
        <box size="0.4 0.10 0.2"/>
      </geometry>
    </collision>
  </link>

  <joint name="joint3" type="revolute">
    <origin rpy="0 0 0.0" xyz="0.45 0.0 0.0"/>
    <axis xyz="0 0 1"/>
    <limit lower="-0.698131701" upper="0.698131701" effort="10.0" velocity="10.0" />
    <parent link="link2"/>
    <child link="link3"/>
  </joint>

  <link name="link3">
    <inertial>
      <mass value="0.1"/>
      <origin xyz="0.0 0.0 0.0"/>
      <inertia ixx="0.1" ixy="0" ixz="0" iyy="0.1" iyz="0" izz="0.1"/>
    </inertial>
    
    <visual>
      <origin rpy="0 0 1.57" xyz="0 0.67 0.0"/>
      <geometry>
        <mesh filename="package://irp6_defs/meshes/link3.3ds" scale="0.01 0.01 0.01" />
      </geometry>
    </visual>
    
    <collision>
      <origin rpy="0 0 0.0" xyz="0 0.3 0.0"/>
      <geometry>
        <box size="0.10 0.67 0.15"/>
      </geometry>
    </collision>
  </link>

  <joint name="joint4" type="revolute">
    <origin rpy="0 0 0" xyz="0.0 0.67 0.0"/>
    <axis xyz="0 0 1"/>
    <limit lower="-1.57" upper="1.57" effort="10.0" velocity="10.0" />
    <parent link="link3"/>
    <child link="link4"/>
  </joint>

  <link name="link4">
    <inertial>
      <mass value="0.1"/>
      <origin xyz="0.0 0.0 0.0"/>
      <inertia ixx="0.1" ixy="0" ixz="0" iyy="0.1" iyz="0" izz="0.1"/>
    </inertial>
    
    <visual>
      <origin rpy="1.57 0 1.57" xyz="0.0 0.175 0.0"/>
      <geometry>
        <mesh filename="package://irp6_defs/meshes/link4.3ds" scale="0.01 0.01 0.01" />
      </geometry>
    </visual>

  </link>

  <joint name="joint5" type="revolute">
    <origin rpy="${-0.5 * M_PI} 0 0" xyz="0.0 0.0 0.0"/>
    <axis xyz="0 0 1"/>
    <limit lower="0.0" upper="3.14" effort="10.0" velocity="10.0" />
    <parent link="link4"/>
    <child link="link5"/>
  </joint>

  <link name="link5">
    <inertial>
      <mass value="0.1"/>
      <origin xyz="0.0 0.0 0.0"/>
      <inertia ixx="0.1" ixy="0" ixz="0" iyy="0.1" iyz="0" izz="0.1"/>
    </inertial>

    <visual>
      <origin rpy="1.57 0 0.0" xyz="0.0 0.0 0.2"/>
      <geometry>
        <mesh filename="package://irp6_defs/meshes/link5.3ds" scale="0.01 0.01 0.01" />
      </geometry>
    </visual>

    <collision>
      <origin rpy="1.57 0 0.0" xyz="0 0.12 0.2"/>
      <geometry>
        <cylinder radius="0.05" length="0.30" />
      </geometry>
    </collision>

  </link>

  <joint name="joint6" type="revolute">
    <origin rpy="${0.5 * M_PI} 0 0" xyz="0.0 -0.1 0.2"/>
    <axis xyz="0 0 1"/>
    <limit lower="0.0" upper="3.14" effort="10.0" velocity="10.0" />
    <parent link="link5"/>
    <child link="link6"/>
  </joint>
  
  <link name="link6">
    <inertial>
      <mass value="0.1"/>
      <origin xyz="0.0 0.0 0.0"/>
      <inertia ixx="0.1" ixy="0" ixz="0" iyy="0.1" iyz="0" izz="0.1"/>
    </inertial>

    <visual>
      <origin rpy="0 0 0.0" xyz="0 0.0 0.0"/>
      <geometry>
         <mesh filename="package://irp6_defs/meshes/link6.3ds" scale="0.01 0.01 0.01" />
      </geometry>
    </visual>

    <collision>
      <origin rpy="0.0 0 0.0" xyz="0 0.0 -0.04"/>
      <geometry>
        <cylinder radius="0.1" length="0.08" />
      </geometry>
    </collision>
  </link>
<!--
  <joint name="laser_tilt" type="revolute">
    <origin rpy="${0.5 * M_PI} 0 0" xyz="0.0 -0.1 2.2"/>
    <axis xyz="0 0 1"/>
    <limit lower="0.0" upper="3.14" effort="10.0" velocity="10.0" />
    <parent link="base_link"/>
    <child link="laser_link"/>
  </joint>
  
  <link name="laser_link">
    <inertial>
      <mass value="0.1"/>
      <origin xyz="0.0 0.0 0.0"/>
      <inertia ixx="0.1" ixy="0" ixz="0" iyy="0.1" iyz="0" izz="0.1"/>
    </inertial>

  </link>
-->
</robot>
